2024-05-15 13:54:22,820 INFO: Printing the data: {'username': 'bob', 'password': 'Superuser1'} [in users.py:87]
2024-05-15 13:54:22,820 INFO: Validation successful. Validated data: {'username': 'bob', 'password': 'Superuser1'} [in users.py:93]
2024-05-15 13:54:22,858 INFO: User found: bob [in users.py:101]
2024-05-15 13:54:22,858 INFO: Attempting to validate password for user: bob [in users.py:108]
2024-05-15 13:54:22,936 INFO: Login successful for user: bob. Generating access token... [in users.py:116]
2024-05-15 13:54:22,937 INFO: Printing the response: <Response 477 bytes [200 OK]> [in users.py:129]
2024-05-15 16:36:59,407 INFO: PGVector extension enabled successfully. [in helper_functions.py:191]
2024-05-15 16:38:31,525 INFO: PGVector extension enabled successfully. [in helper_functions.py:191]
2024-05-15 16:39:24,304 INFO: PGVector extension enabled successfully. [in helper_functions.py:191]
2024-05-15 16:40:49,913 INFO: PGVector extension enabled successfully. [in helper_functions.py:191]
2024-05-15 16:41:38,945 INFO: Printing the data: {'username': 'bob', 'password': 'Superuser1'} [in users.py:87]
2024-05-15 16:41:38,946 INFO: Validation successful. Validated data: {'username': 'bob', 'password': 'Superuser1'} [in users.py:93]
2024-05-15 16:41:38,988 INFO: User found: bob [in users.py:101]
2024-05-15 16:41:38,988 INFO: Attempting to validate password for user: bob [in users.py:108]
2024-05-15 16:41:39,071 INFO: Login successful for user: bob. Generating access token... [in users.py:116]
2024-05-15 16:41:39,072 INFO: Printing the response: <Response 477 bytes [200 OK]> [in users.py:129]
2024-05-15 16:42:52,958 ERROR: Error handling query: Incorrect number of values in identifier to formulate primary key for session.get(); primary key columns are 'users.id' [in chatbot.py:60]
2024-05-16 08:48:31,981 INFO: PGVector extension enabled successfully. [in helper_functions.py:191]
2024-05-16 08:48:44,067 INFO: Printing the data: {'username': 'bob', 'password': 'Superuser1'} [in users.py:87]
2024-05-16 08:48:44,067 INFO: Validation successful. Validated data: {'username': 'bob', 'password': 'Superuser1'} [in users.py:93]
2024-05-16 08:48:44,108 INFO: User found: bob [in users.py:101]
2024-05-16 08:48:44,108 INFO: Attempting to validate password for user: bob [in users.py:108]
2024-05-16 08:48:44,208 INFO: Login successful for user: bob. Generating access token... [in users.py:116]
2024-05-16 08:48:44,209 INFO: Printing the response: <Response 477 bytes [200 OK]> [in users.py:129]
